[2024-09-27T09:37:11.801+0000] {local_task_job_runner.py:123} INFO - ::group::Pre task execution logs
[2024-09-27T09:37:11.823+0000] {taskinstance.py:2612} INFO - Dependencies all met for dep_context=non-requeueable deps ti=<TaskInstance: sparking_flow.clear_data manual__2024-09-27T09:37:04.964832+00:00 [queued]>
[2024-09-27T09:37:11.836+0000] {taskinstance.py:2612} INFO - Dependencies all met for dep_context=requeueable deps ti=<TaskInstance: sparking_flow.clear_data manual__2024-09-27T09:37:04.964832+00:00 [queued]>
[2024-09-27T09:37:11.837+0000] {taskinstance.py:2865} INFO - Starting attempt 1 of 1
[2024-09-27T09:37:11.857+0000] {taskinstance.py:2888} INFO - Executing <Task(SparkSubmitOperator): clear_data> on 2024-09-27 09:37:04.964832+00:00
[2024-09-27T09:37:11.865+0000] {warnings.py:112} WARNING - /home/***/.local/lib/python3.12/site-packages/***/task/task_runner/standard_task_runner.py:70: DeprecationWarning: This process (pid=133) is multi-threaded, use of fork() may lead to deadlocks in the child.
  pid = os.fork()

[2024-09-27T09:37:11.866+0000] {standard_task_runner.py:72} INFO - Started process 134 to run task
[2024-09-27T09:37:11.867+0000] {standard_task_runner.py:104} INFO - Running: ['***', 'tasks', 'run', 'sparking_flow', 'clear_data', 'manual__2024-09-27T09:37:04.964832+00:00', '--job-id', '11', '--raw', '--subdir', 'DAGS_FOLDER/spark_***.py', '--cfg-path', '/tmp/tmpa168tfvt']
[2024-09-27T09:37:11.869+0000] {standard_task_runner.py:105} INFO - Job 11: Subtask clear_data
[2024-09-27T09:37:11.927+0000] {task_command.py:467} INFO - Running <TaskInstance: sparking_flow.clear_data manual__2024-09-27T09:37:04.964832+00:00 [running]> on host 84f8fd3cc01e
[2024-09-27T09:37:12.030+0000] {taskinstance.py:3131} INFO - Exporting env vars: AIRFLOW_CTX_DAG_OWNER='***' AIRFLOW_CTX_DAG_ID='sparking_flow' AIRFLOW_CTX_TASK_ID='clear_data' AIRFLOW_CTX_EXECUTION_DATE='2024-09-27T09:37:04.964832+00:00' AIRFLOW_CTX_TRY_NUMBER='1' AIRFLOW_CTX_DAG_RUN_ID='manual__2024-09-27T09:37:04.964832+00:00'
[2024-09-27T09:37:12.032+0000] {taskinstance.py:731} INFO - ::endgroup::
[2024-09-27T09:37:12.065+0000] {spark_submit.py:273} INFO - Could not load connection string spark-conn, defaulting to yarn
[2024-09-27T09:37:12.067+0000] {spark_submit.py:403} INFO - Spark-Submit cmd: spark-submit --master yarn --name arrow-spark jobs/python/clear_data.py
[2024-09-27T09:37:12.165+0000] {spark_submit.py:579} INFO - /home/***/.local/lib/python3.12/site-packages/pyspark/bin/load-spark-env.sh: line 68: ps: command not found
[2024-09-27T09:37:17.301+0000] {spark_submit.py:579} INFO - Exception in thread "main" org.apache.spark.SparkException: When running with master 'yarn' either HADOOP_CONF_DIR or YARN_CONF_DIR must be set in the environment.
[2024-09-27T09:37:17.302+0000] {spark_submit.py:579} INFO - at org.apache.spark.deploy.SparkSubmitArguments.error(SparkSubmitArguments.scala:650)
[2024-09-27T09:37:17.303+0000] {spark_submit.py:579} INFO - at org.apache.spark.deploy.SparkSubmitArguments.validateSubmitArguments(SparkSubmitArguments.scala:281)
[2024-09-27T09:37:17.304+0000] {spark_submit.py:579} INFO - at org.apache.spark.deploy.SparkSubmitArguments.validateArguments(SparkSubmitArguments.scala:237)
[2024-09-27T09:37:17.305+0000] {spark_submit.py:579} INFO - at org.apache.spark.deploy.SparkSubmitArguments.<init>(SparkSubmitArguments.scala:122)
[2024-09-27T09:37:17.306+0000] {spark_submit.py:579} INFO - at org.apache.spark.deploy.SparkSubmit$$anon$2$$anon$3.<init>(SparkSubmit.scala:1103)
[2024-09-27T09:37:17.307+0000] {spark_submit.py:579} INFO - at org.apache.spark.deploy.SparkSubmit$$anon$2.parseArguments(SparkSubmit.scala:1103)
[2024-09-27T09:37:17.307+0000] {spark_submit.py:579} INFO - at org.apache.spark.deploy.SparkSubmit.doSubmit(SparkSubmit.scala:86)
[2024-09-27T09:37:17.308+0000] {spark_submit.py:579} INFO - at org.apache.spark.deploy.SparkSubmit$$anon$2.doSubmit(SparkSubmit.scala:1120)
[2024-09-27T09:37:17.309+0000] {spark_submit.py:579} INFO - at org.apache.spark.deploy.SparkSubmit$.main(SparkSubmit.scala:1129)
[2024-09-27T09:37:17.310+0000] {spark_submit.py:579} INFO - at org.apache.spark.deploy.SparkSubmit.main(SparkSubmit.scala)
[2024-09-27T09:37:17.334+0000] {taskinstance.py:3310} ERROR - Task failed with exception
Traceback (most recent call last):
  File "/home/airflow/.local/lib/python3.12/site-packages/airflow/models/taskinstance.py", line 767, in _execute_task
    result = _execute_callable(context=context, **execute_callable_kwargs)
             ^^^^^^^^^^^^^^^^^^^^^^^^^^^^^^^^^^^^^^^^^^^^^^^^^^^^^^^^^^^^^
  File "/home/airflow/.local/lib/python3.12/site-packages/airflow/models/taskinstance.py", line 733, in _execute_callable
    return ExecutionCallableRunner(
           ^^^^^^^^^^^^^^^^^^^^^^^^
  File "/home/airflow/.local/lib/python3.12/site-packages/airflow/utils/operator_helpers.py", line 252, in run
    return self.func(*args, **kwargs)
           ^^^^^^^^^^^^^^^^^^^^^^^^^^
  File "/home/airflow/.local/lib/python3.12/site-packages/airflow/models/baseoperator.py", line 406, in wrapper
    return func(self, *args, **kwargs)
           ^^^^^^^^^^^^^^^^^^^^^^^^^^^
  File "/home/airflow/.local/lib/python3.12/site-packages/airflow/providers/apache/spark/operators/spark_submit.py", line 174, in execute
    self._hook.submit(self.application)
  File "/home/airflow/.local/lib/python3.12/site-packages/airflow/providers/apache/spark/hooks/spark_submit.py", line 505, in submit
    raise AirflowException(
airflow.exceptions.AirflowException: Cannot execute: spark-submit --master yarn --name arrow-spark jobs/python/clear_data.py. Error code is: 1.
[2024-09-27T09:37:17.347+0000] {taskinstance.py:1225} INFO - Marking task as FAILED. dag_id=sparking_flow, task_id=clear_data, run_id=manual__2024-09-27T09:37:04.964832+00:00, execution_date=20240927T093704, start_date=20240927T093711, end_date=20240927T093717
[2024-09-27T09:37:17.367+0000] {taskinstance.py:340} INFO - ::group::Post task execution logs
[2024-09-27T09:37:17.368+0000] {standard_task_runner.py:124} ERROR - Failed to execute job 11 for task clear_data (Cannot execute: spark-submit --master yarn --name arrow-spark jobs/python/clear_data.py. Error code is: 1.; 134)
Traceback (most recent call last):
  File "/home/airflow/.local/lib/python3.12/site-packages/airflow/task/task_runner/standard_task_runner.py", line 117, in _start_by_fork
    ret = args.func(args, dag=self.dag)
          ^^^^^^^^^^^^^^^^^^^^^^^^^^^^^
  File "/home/airflow/.local/lib/python3.12/site-packages/airflow/cli/cli_config.py", line 49, in command
    return func(*args, **kwargs)
           ^^^^^^^^^^^^^^^^^^^^^
  File "/home/airflow/.local/lib/python3.12/site-packages/airflow/utils/cli.py", line 115, in wrapper
    return f(*args, **kwargs)
           ^^^^^^^^^^^^^^^^^^
  File "/home/airflow/.local/lib/python3.12/site-packages/airflow/cli/commands/task_command.py", line 483, in task_run
    task_return_code = _run_task_by_selected_method(args, _dag, ti)
                       ^^^^^^^^^^^^^^^^^^^^^^^^^^^^^^^^^^^^^^^^^^^^
  File "/home/airflow/.local/lib/python3.12/site-packages/airflow/cli/commands/task_command.py", line 256, in _run_task_by_selected_method
    return _run_raw_task(args, ti)
           ^^^^^^^^^^^^^^^^^^^^^^^
  File "/home/airflow/.local/lib/python3.12/site-packages/airflow/cli/commands/task_command.py", line 341, in _run_raw_task
    return ti._run_raw_task(
           ^^^^^^^^^^^^^^^^^
  File "/home/airflow/.local/lib/python3.12/site-packages/airflow/utils/session.py", line 97, in wrapper
    return func(*args, session=session, **kwargs)
           ^^^^^^^^^^^^^^^^^^^^^^^^^^^^^^^^^^^^^^
  File "/home/airflow/.local/lib/python3.12/site-packages/airflow/models/taskinstance.py", line 3004, in _run_raw_task
    return _run_raw_task(
           ^^^^^^^^^^^^^^
  File "/home/airflow/.local/lib/python3.12/site-packages/airflow/models/taskinstance.py", line 273, in _run_raw_task
    TaskInstance._execute_task_with_callbacks(
  File "/home/airflow/.local/lib/python3.12/site-packages/airflow/models/taskinstance.py", line 3158, in _execute_task_with_callbacks
    result = self._execute_task(context, task_orig)
             ^^^^^^^^^^^^^^^^^^^^^^^^^^^^^^^^^^^^^^
  File "/home/airflow/.local/lib/python3.12/site-packages/airflow/models/taskinstance.py", line 3182, in _execute_task
    return _execute_task(self, context, task_orig)
           ^^^^^^^^^^^^^^^^^^^^^^^^^^^^^^^^^^^^^^^
  File "/home/airflow/.local/lib/python3.12/site-packages/airflow/models/taskinstance.py", line 767, in _execute_task
    result = _execute_callable(context=context, **execute_callable_kwargs)
             ^^^^^^^^^^^^^^^^^^^^^^^^^^^^^^^^^^^^^^^^^^^^^^^^^^^^^^^^^^^^^
  File "/home/airflow/.local/lib/python3.12/site-packages/airflow/models/taskinstance.py", line 733, in _execute_callable
    return ExecutionCallableRunner(
           ^^^^^^^^^^^^^^^^^^^^^^^^
  File "/home/airflow/.local/lib/python3.12/site-packages/airflow/utils/operator_helpers.py", line 252, in run
    return self.func(*args, **kwargs)
           ^^^^^^^^^^^^^^^^^^^^^^^^^^
  File "/home/airflow/.local/lib/python3.12/site-packages/airflow/models/baseoperator.py", line 406, in wrapper
    return func(self, *args, **kwargs)
           ^^^^^^^^^^^^^^^^^^^^^^^^^^^
  File "/home/airflow/.local/lib/python3.12/site-packages/airflow/providers/apache/spark/operators/spark_submit.py", line 174, in execute
    self._hook.submit(self.application)
  File "/home/airflow/.local/lib/python3.12/site-packages/airflow/providers/apache/spark/hooks/spark_submit.py", line 505, in submit
    raise AirflowException(
airflow.exceptions.AirflowException: Cannot execute: spark-submit --master yarn --name arrow-spark jobs/python/clear_data.py. Error code is: 1.
[2024-09-27T09:37:17.420+0000] {local_task_job_runner.py:266} INFO - Task exited with return code 1
[2024-09-27T09:37:17.448+0000] {taskinstance.py:3900} INFO - 0 downstream tasks scheduled from follow-on schedule check
[2024-09-27T09:37:17.456+0000] {local_task_job_runner.py:245} INFO - ::endgroup::
